Workbook

Sheet IT (2)
H1: Appendix 45
L2: Liquidation: (2 pcs)
A3: ACTUAL ITINERARY OF TRAVEL | M3: Liquidation Report | Q3: OR
M4: Itenerary | Q4: Communicatiom
M5: Cert of Travel Compl | Q5: TO
A6: Entity Name : BOHOL ISLAND STATE UNIVERSITY CANDIJAY CAMPUS | M6: Cert of Not Req. Recipt | Q6: Cert of Appearance
A7: Fund Cluster: ____________________ | H7: No.: | M7: Tickets | Q7: Cert of Recognition
A9: Name : | B9: ROGER E. AMOLATO | F9: Date of Travel: | G9: October 30, 2025
A10: Position : | B10: =Source!A2 -> Instructor I - Temporary
A11: =CONCATENATE("Official Station: ",Source!A3) -> Official Station: | B11: Bohol Island State University - Candijay Campus
F12: Purpose of Travel :
F13: To attend the Solidarity Meeting and Submission of Lacking Documents for the University Paugnat and Pasundayag Festival 2025 on October 30, 2025, at the BISU Main Campus Activity Center, Tagbilaran City, Bohol.
L14: =180*3 -> 540
A17: Date | B17: Places to be visited | D17: T I M E | F17: Means of | G17: Transpor-station | H17: Per | I17: Others | J17: Total Amount
B18: (Destination) | D18: Departure | E18: Arrival | F18: Transportation | H18: Diem | K18: bf | L18: incidental | M18: lunch | N18: incidental | O18: dinner
A19: October 30, 2025 | B19: Station to BISU Main | D19: 0.25 | E19: 0.32291667 | F19: Gov't Transpo | H19: 540 | J19: =G19+H19+I19 -> 540 | L19: 180 | M19: 180 | N19: 180
B20: BISU Main to Station
B40: TOTAL | C40: FIVE HUNDRED FORTY PESOS ONLY | I40: P | J40: =SUM(J19:J39) -> 540 | L40: =17020-J40 -> 16480 | N40: =L40-J40 -> 15940
E41: Prepared by :
A43: I certify that : (1) I have reviewed the foregoing itinerary, (2) the travel is necessary to the service, (3) the period covered is reasonable and (4) the expenses claimed are proper. | E43: =B9 -> ROGER E. AMOLATO
E44: Signature over Printed Name
E46: Approved by:
A50: MARK JUBEN M. PILAPIL | E50: LUZMINDA G. MACHETE, EdD
A51: Signature over Printed Name | E51: Signature over Printed Name
A52: Immediate Supervisor | E52: Agency Head/Authorized Representative

Sheet CTC (2)
A2: APPENDIX 47
A4: CERTIFICATION OF TRAVEL COMPLETED
A6: Entity Name : BOHOL ISLAND STATE UNIVERSITY | F6: Fund Cluster: _______________
B9: LUZMINDA G. MACHETE, EdD | G9: Candijay Campus
B10: Director In-Charge | G10: Station
A13: I HEREBY CERTIFY THAT I have completed the travel as authorized in the Travel Order/
A14: Itinerary of Travel No. __________ dated ___________ under conditions indicated below:
B17: / x / | C17: Strictly in accordance with the approved itinerary.
B18: / / | C18: Cut short as explain below. Excess payment in the amount of
C19: P _______ was refunded under O.R. No. _________ dated __________
B20: / / | C20: Extended as explained below, additional itinerary was submitted
B21: / / | C21: Other deviation as explained below.
A23: Explanation or justifications:
A26: Evidence of Travel:
A28: Certificate of Appearance
F33: Respectfully submitted:
F36: ROGER E. AMOLATO
F37: Instructor I-Temporary
B39: On evidence and information of which I have the knowledge, the travel was actually
A40: undertaken.
F42: Approved:
F45: LUZMINDA G. MACHETE, EdD
F46: Campus Director

Sheet DV (2)
AB1: Appendix 32
A3: BOHOL ISLAND STATE UNIVERSITY | AB3: Fund Cluster :
A4: Entity Name
A5: DISBURSEMENT VOUCHER | AB5: Date :
AB6: DV No. :
A8: Mode of Payment
H9: MDS Check | M9: Commercial Check | T9: ADA | W9: X | X9: Others (Please specify) | AL9: 632
AA10: _________________
A11: Payee | E11: ROGER E. AMOLATO | S11: TIN/Employee No.: | AB11: ORS/BURS No.:
A13: Address | E13: BISU Candijay Campus
A15: Particulars | R15: Responsibility Center | W15: MFO/PAP | AB15: Amount
A16: 2025
A17: Reimbursement of the travelling expenses to attend the Solidarity Meeting and Submission of Lacking Documents for the University Paugnat and Pasundayag Festival 2025 on October 30, 2025, at the BISU Main Campus Activity Center, Tagbilaran City, Bohol.
AB19: PHP | AE19: ='IT (2)'!J40 -> 540
A26: Amount Due | AB26: Php | AE26: =AE19 -> 540
A27: A. | B27: Certified: Expenses/Cash Advance necessary, lawful and incurred under my direct supervision.
A29: ='IT (2)'!A50:D50 -> MARK JUBEN M. PILAPIL
A30: Director, Sports
A31: Printed Name, Designation and Signature of Supervisor
A33: B. | B33: Accounting Entry:
A34: Account Title | S34: UACS Code | X34: Debit | AC34: Credit
X35: =AE26 -> 540
AC37: =X35 -> 540
A38: C. | B38: Certified: | S38: D. | T38: Approved for Payment
C39: Cash available | S39: FIVE HUNDRED FORTY PESOS ONLY
C41: Subject to Authority to Debit Account (when applicable)
C43: Supporting documents complete and amount claimed | D43: Supporting documents complete and amount claimed
C44: proper
A46: Signature | S46: Signature
A48: Printed Name | E48: MARLINA S. UY | S48: Printed Name | W48: LUZMINDA G. MACHETE, EdD
A50: Position | E50: Admin Asst. II/ Bookkeeper | S50: Position | W50: Campus Director
E51: Head, Accounting Unit/Authorized Representative | W51: Agency Head/Authorized Representative
A52: Date | S52: Date
A54: E. | B54: Receipt of Payment | AB54: JEV No.
A55: Check/ ADA No. : | N55: Date : | S55: Bank Name & Account Number:
A57: Signature : | N57: Date : | S57: Printed Name: BOBBY LOU P. CURAY, et.al | AB57: Date
S58: =E11 -> ROGER E. AMOLATO
A59: Official Receipt No. & Date/Other Documents

Sheet burs r 3 (2)
L1: Appendix 11
A4: BUDGET UTILIZATION REQUEST AND STATUS | K4: Serial No. : ___________________
A5: BOHOL ISLAND STATE UNIVERSITY | K5: Date : _______________________
A6: Entity Name | K6: Fund Cluster :_________________
A8: Payee | D8: ='DV (2)'!E11 -> ROGER E. AMOLATO
A10: Office | D10: College of Sciences
A12: Address | D12: BISU Candijay Campus
A14: Responsibility Center | D14: Particulars | I14: MFO/PAP | K14: UACS Object Code | L14: Amount
D16: 2025
D17: Reimbursement of the travelling expenses to attend the Solidarity Meeting and Submission of Lacking Documents for the University Paugnat and Pasundayag Festival 2025 on October 30, 2025, at the BISU Main Campus Activity Center, Tagbilaran City, Bohol.
L20: ='DV (2)'!AE26 -> 540
D25: Total | L25: =L20 -> 540
A26: A. | I26: B.
B27: Certified: | D27: Charges to appropriation/budget necessary, | J27: Certified: Budget available and utilized for
B28: lawful and under my direct supervision; and supporting | J28: the purpose/adjustment necessary as
B29: documents valid, proper and legal | J29: indicated above
A33: Signature : | C33: ____________________________________ | I33: Signature : | K33: _________________________________
A35: Printed Name: | C35: ='DV (2)'!A29 -> MARK JUBEN M. PILAPIL | I35: Printed Name: | K35: MARLINA S. UY
A36: Position : | C36: Director, Sports | I36: Position : | K36: Budget Designate
C37: Head, Requesting Office/Authorized Representative | K37: Head, Budget Division/Unit/Authorized Representative
A38: Date : | C38: _______________________________ | I38: Date : | K38: ____________________________
A41: C. | B41: STATUS OF UTILIZATION
A42: Reference | H42: Amount
A43: Date | B43: Particulars | E43: ORS/JEV/Check/ ADA/TRA No. | H43: Obligation | I43: Payable | K43: Payment | L43: Balance
L44: Not Yet Due | M44: Due and Demandable
H45: (a) | I45: (b) | K45: (c) | L45: (a-b) | M45: (b-c)
A46: October 30, 2025 | B46: =D17 -> Reimbursement of the travelling expenses to attend the Solidarity Meeting and Submission of Lacking Documents for the University Paugnat and Pasundayag Festival 2025 on October 30, 2025, at the BISU Main Campus Activity Center, Tagbilaran City, Bohol.
H48: =L25 -> 540 | K48: =H48 -> 540 | M48: =K48 -> 540

Sheet obs r 3
L1: Appendix 11
A4: OBLIGATION REQUEST AND STATUS | K4: Serial No. : ___________________
A5: BOHOL ISLAND STATE UNIVERSITY | K5: Date : _______________________
A6: Entity Name | K6: Fund Cluster :_________________
A8: Payee | D8: ='DV (2)'!E11 -> ROGER E. AMOLATO
A10: Office | D10: College of Sciences
A12: Address | D12: BISU Candijay Campus
A14: Responsibility Center | D14: Particulars | I14: MFO/PAP | K14: UACS Object Code | L14: Amount
D16: 2025
D17: Reimbursement of the travelling expenses to deposit payments for the registration of the 27th PSITE National Convention on February 24, 2025, in China Bank, Tagbilaran City, and to submit pertinent documents for the Educational Tour for BSCS in BISU - Main Campus, Tagbilaran City, on April 21, 2025
L20: ='DV (2)'!AE26 -> 540
D25: Total | L25: =L20 -> 540
A26: A. | I26: B.
B27: Certified: | D27: Charges to appropriation/budget necessary, | J27: Certified: Budget available and utilized for
B28: lawful and under my direct supervision; and supporting | J28: the purpose/adjustment necessary as
B29: documents valid, proper and legal | J29: indicated above
A33: Signature : | C33: ____________________________________ | I33: Signature : | K33: _________________________________
A35: Printed Name: | C35: ='DV (2)'!A29 -> MARK JUBEN M. PILAPIL | I35: Printed Name: | K35: MARLINA S. UY
A36: Position : | C36: Dean, College of Sciences | I36: Position : | K36: Budget Designate
C37: Head, Requesting Office/Authorized Representative | K37: Head, Budget Division/Unit/Authorized Representative
A38: Date : | C38: _______________________________ | I38: Date : | K38: ____________________________
A41: C. | B41: STATUS OF UTILIZATION
A42: Reference | H42: Amount
A43: Date | B43: Particulars | E43: ORS/JEV/Check/ ADA/TRA No. | H43: Obligation | I43: Payable | K43: Payment | L43: Balance
L44: Not Yet Due | M44: Due and Demandable
H45: (a) | I45: (b) | K45: (c) | L45: (a-b) | M45: (b-c)
A46: May 4-6, 2023 | B46: =D17 -> Reimbursement of the travelling expenses to deposit payments for the registration of the 27th PSITE National Convention on February 24, 2025, in China Bank, Tagbilaran City, and to submit pertinent documents for the Educational Tour for BSCS in BISU - Main Campus, Tagbilaran City, on April 21, 2025
H48: =L25 -> 540 | K48: =H48 -> 540 | M48: =K48 -> 540

Sheet IT
H1: Appendix 45
A3: ACTUAL ITINERARY OF TRAVEL
A6: Entity Name : BOHOL ISLAND STATE UNIVERSITY CANDIJAY CAMPUS
A7: Fund Cluster: ____________________ | H7: No.:
A9: Name : | B9: =ORS!D6 -> ROGER E. AMOLATO | F9: Date of Travel: | G9: =Source!A6 -> November 14-15, 18 and 22-23, 2022
A10: Position : | B10: =Source!A2 -> Instructor I - Temporary | F10: Purpose of Travel :
A11: =CONCATENATE("Official Station: ",Source!A3) -> Official Station:
F12: Purpose of Travel :
F13: =CONCATENATE(Source!A7, " at ",Source!A8,) -> to attend and participate the Crafting of University Land Use Development and Infrastructure Plan and attend University BAC Meeting at JJs Seafood and Restaurant and BISU Main Campus respectively
O14: =180*3 -> 540
A17: Date | B17: Places to be visited | D17: T I M E | F17: Means of | G17: Transpor-station | H17: Per | I17: Others | J17: Total Amount
B18: (Destination) | D18: Departure | E18: Arrival | F18: Transportation | H18: Diem
A19: November 14, 2022 | B19: Candijay-JJs Seafood | D19: 0.25 | E19: 0.33333333 | F19: Van | G19: 180 | H19: =1800-180 -> 1620 | J19: =G19+H19+I19 -> 1800 | K19: free lunch | N19: bf | O19: incidental | P19: lunch | Q19: incidental | R19: dinner
B20: and Restaurant | N20: 180 | O20: 180 | Q20: 180 | R20: 180
B21: Workshop Proper | D21: 0.35416667 | E21: 0.70833333 | M21: 180
A22: November 15, 2022 | D22: 0.33333333 | E22: 0.70833333 | H22: =1800-180-900 -> 720 | J22: =G22+H22+I22 -> 720 | K22: free lunch | L22: =720-180 -> 540 | M22: 180
B23: JJs Seafood and Restaurant to Candijay | D23: 0.72916667 | E23: 0.8125 | F23: Sportivo | M23: =720/180 -> 4
A25: November 18, 2022 | B25: Candijay to BISU Main | D25: 0.36458333 | E25: 0.44791667 | F25: Sportivo | H25: 720 | J25: =SUM(G25:H25) -> 720 | K25: breakfast excluded | M25: 900 | N25: 180 | O25: 180 | P25: 180 | Q25: 180 | R25: 180
B26: BAC Meeting | D26: 0.44791667 | E26: 0.70833333
B27: BISU Main to Candijay | D27: 0.72916667 | E27: 0.8125 | F27: Sportivo
A28: November 22, 2022 | B28: Candijay- JJs Seafood | D28: 0.25 | E28: 0.41666667 | F28: Sportivo | H28: 1620 | J28: =G28+H28+I28 -> 1620 | K28: free lunch | M28: =540+900 -> 1440
B29: and Restaurant
B30: Workshop Proper | D30: 0.375 | E30: 0.70833333
A31: November 23, 2022 | B31: Workshop Proper | D31: 0.33333333 | E31: 0.70833333
B32: JJs Seafood and Restaurant to Candijay | D32: 0.73958333 | E32: 0.82291667 | F32: Sportivo | H32: 720 | J32: =G32+H32+I32 -> 720 | K32: free lunch
B34: TOTAL | C34: Five thousand five hundred eighty pesos only | I34: P | J34: =SUM(J19:J33) -> 5580
E35: Prepared by :
A37: I certify that : (1) I have reviewed the foregoing itinerary, (2) the travel is necessary to the service, (3) the period covered is reasonable and (4) the expenses claimed are proper. | E37: =B9 -> ROGER E. AMOLATO
E38: Signature over Printed Name
E40: Approved by:
A44: ='obs r 3'!C35 -> MARK JUBEN M. PILAPIL | E44: LUZMINDA G. MACHETE, EdD
A45: Signature over Printed Name | E45: Signature over Printed Name
A46: Immediate Supervisor | E46: Agency Head/Authorized Representative

Sheet Certification 1
A1: Republic of the Philippines
A2: Bohol Island State University
A3: Cogtong, Candijay, Bohol
A5: ANNEX A
A6: CERTIFICATION OF EXPENSES NOT REQUIRING RECEIPTS
A7: Pursuant to COA Circular No. 2017-001- dated June 19, 2017
A8: Name of Employee | C8: =IT!B9 -> ROGER E. AMOLATO | G8: Employee No.
A9: Office | B9: BOHOL ISLAND STATE UNIVERSITY
A10: Division | B10: CANDIJAY CAMPUS
A11: Particulars | H11: Amount ((₱)
A12: Van Fare (Candijay-Tagbilaran) | H12: 180
A16: TOTAL | H16: =SUM(H12:H15) -> 180
A17: Purpose
A18: to attend and participate the Crafting of University Land Use Development and Infrastructure Plan at JJs Seafood and Restaurant
A19: I hereby certify that the above expenses are incurred as they are necessary for the above cited purpose that above goods and services were acquired from parties not issuing receipts. And that I am fully aware that wilful falsification of statements is punishable by law.
D22: Certified Correct: | G22: Noted By:
A23: Signature:
A24: Printed Name: | D24: =C8 -> ROGER E. AMOLATO | G24: =IT!A44 -> MARK JUBEN M. PILAPIL
D26: =Source!A2 -> Instructor I - Temporary | G26: Immediate Supervisor
D27: Date | G27: Date
A29: Republic of the Philippines
A30: Bohol Island State University
A31: Cogtong, Candijay, Bohol
A33: ANNEX A
A34: CERTIFICATION OF EXPENSES NOT REQUIRING RECEIPTS
A35: Pursuant to COA Circular No. 2017-001- dated June 19, 2017
A36: Name of Employee | C36: =C8 -> ROGER E. AMOLATO | G36: Employee No.
A37: Office | B37: BOHOL ISLAND STATE UNIVERSITY
A38: Division | B38: CANDIJAY CAMPUS
A39: Particulars | H39: Amount ((₱)
A40: Van Fare (Candijay-Tagbilaran) | H40: 180
H42: =H14 -> 0
H43: =H15 -> 0
A44: TOTAL | H44: =SUM(H40:H43) -> 180
A45: Purpose
A46: =A18 -> to attend and participate the Crafting of University Land Use Development and Infrastructure Plan at JJs Seafood and Restaurant
A47: I hereby certify that the above expenses are incurred as they are necessary for the above cited purpose that above goods and services were acquired from parties not issuing receipts. And that I am fully aware that wilful falsification of statements is punishable by law.
D50: Certified Correct: | G50: Noted By:
A51: Signature:
A52: Printed Name: | D52: =C36 -> ROGER E. AMOLATO | G52: =G24 -> MARK JUBEN M. PILAPIL
...

Sheet burs 3
L1: Appendix 14
A4: BUDGET UTILIZATION REQUEST AND STATUS | K4: Serial No. : ___________________
A5: BOHOL ISLAND STATE UNIVERSITY | K5: Date : _______________________
A6: Entity Name | K6: Fund Cluster :_________________
A8: Payee | D8: ='DV (2)'!E11 -> ROGER E. AMOLATO
A10: Office | D10: CTAS
A12: Address | D12: BISU Candijay Campus
A14: Responsibility Center | D14: Particulars | I14: MFO/PAP | K14: UACS Object Code | L14: Amount
D16: 2023
D17: ='DV (2)'!A17 & CHAR(10) &"" -> Reimbursement of the travelling expenses to attend the Solidarity Meeting and Submission of Lacking Documents for the University Paugnat and Pasundayag Festival 2025 on October 30, 2025, at the BISU Main Campus Activity Center, Tagbilaran City, Bohol.
L20: ='DV (2)'!AE26 -> 540
D25: Total | L25: =L20 -> 540
A26: A. | I26: B.
B27: Certified: | D27: Charges to appropriation/budget necessary, | J27: Certified: Budget available and utilized for
B28: lawful and under my direct supervision; and supporting | J28: the purpose/adjustment necessary as
B29: documents valid, proper and legal | J29: indicated above
A33: Signature : | C33: ____________________________________ | I33: Signature : | K33: _________________________________
A35: Printed Name: | C35: ='DV (2)'!A29 -> MARK JUBEN M. PILAPIL | I35: Printed Name: | K35: MARLINA S. UY
A37: Position : | C37: CTAS, Dean | I37: Position : | K37: Budget Designate
C38: Head, Requesting Office/Authorized Representative | K38: Head, Budget Division/Unit/Authorized Representative
A39: Date : | C39: _______________________________ | I39: Date : | K39: ____________________________
A42: C. | B42: STATUS OF UTILIZATION
A43: Reference | H43: Amount
A44: Date | B44: Particulars | E44: ORS/JEV/Check/ ADA/TRA No. | H44: Obligation | I44: Payable | K44: Payment | L44: Balance
L45: Not Yet Due | M45: Due and Demandable
H46: (a) | I46: (b) | K46: (c) | L46: (a-b) | M46: (b-c)
A47: May 4-6, 2023 | B47: =D17 -> Reimbursement of the travelling expenses to attend the Solidarity Meeting and Submission of Lacking Documents for the University Paugnat and Pasundayag Festival 2025 on October 30, 2025, at the BISU Main Campus Activity Center, Tagbilaran City, Bohol.
H49: =L25 -> 540 | K49: =H49 -> 540 | M49: =K49 -> 540

Sheet Certification ('1) (2)
A1: Republic of the Philippines
A2: Bohol Island State University
A3: Cogtong, Candijay, Bohol
A5: ANNEX A
A6: CERTIFICATION OF EXPENSES NOT REQUIRING RECEIPTS
A7: Pursuant to COA Circular No. 2017-001- dated June 19, 2017
A8: Name of Employee | C8: =IT!B9 -> ROGER E. AMOLATO | G8: Employee No. | H8: 85448
A9: Office | B9: BOHOL ISLAND STATE UNIVERSITY
A10: Division | B10: CANDIJAY CAMPUS
A11: Particulars | H11: Amount ((₱)
A12: V-Hire Fare (Anda Terminal - Dao Terminal ) | H12: 200
A16: TOTAL | H16: =SUM(H12:H15) -> 200
A17: Purpose
A18: To visit the Host Training Establishments (HTEs) of the BSCS OJTs on JULY 31, 2025, at Tagbilaran City, Bohol
A19: I hereby certify that the above expenses are incurred as they are necessary for the above cited purpose that above goods and services were acquired from parties not issuing receipts. And that I am fully aware that wilful falsification of statements is punishable by law.
D22: Certified Correct: | G22: Noted By:
A23: Signature:
A24: Printed Name: | D24: =C8 -> ROGER E. AMOLATO | G24: =IT!A44 -> MARK JUBEN M. PILAPIL
D26: =Source!A2 -> Instructor I - Temporary | G26: Immediate Supervisor
D27: Date | G27: Date
A29: Republic of the Philippines
A30: Bohol Island State University
A31: Cogtong, Candijay, Bohol
A33: ANNEX A
A34: CERTIFICATION OF EXPENSES NOT REQUIRING RECEIPTS
A35: Pursuant to COA Circular No. 2017-001- dated June 19, 2017
A36: Name of Employee | C36: =C8 -> ROGER E. AMOLATO | G36: Employee No. | H36: =H8 -> 85448
A37: Office | B37: BOHOL ISLAND STATE UNIVERSITY
A38: Division | B38: CANDIJAY CAMPUS
A39: Particulars | H39: Amount ((₱)
A40: V-Hire Fare (Dao Terminal - Anda Terminal ) | H40: 200
A44: TOTAL | H44: =SUM(H40:H43) -> 200
A45: Purpose
A46: =A18 -> To visit the Host Training Establishments (HTEs) of the BSCS OJTs on JULY 31, 2025, at Tagbilaran City, Bohol
A47: I hereby certify that the above expenses are incurred as they are necessary for the above cited purpose that above goods and services were acquired from parties not issuing receipts. And that I am fully aware that wilful falsification of statements is punishable by law.
D50: Certified Correct: | G50: Noted By:
A51: Signature:
A52: Printed Name: | D52: =C36 -> ROGER E. AMOLATO | G52: =G24 -> MARK JUBEN M. PILAPIL
D54: =D26 -> Instructor I - Temporary | G54: Immediate Supervisor
D55: Date | G55: Date

Sheet Certification ('1) (3)
A1: Republic of the Philippines
A2: Bohol Island State University
A3: Cogtong, Candijay, Bohol
A5: ANNEX A
A6: CERTIFICATION OF EXPENSES NOT REQUIRING RECEIPTS
A7: Pursuant to COA Circular No. 2017-001- dated June 19, 2017
A8: Name of Employee | C8: =IT!B9 -> ROGER E. AMOLATO | G8: Employee No. | H8: 85448
A9: Office | B9: BOHOL ISLAND STATE UNIVERSITY
A10: Division | B10: CANDIJAY CAMPUS
A11: Particulars | H11: Amount ((₱)
A12: V-Hire Fare (Anda Terminal - Dao Terminal ) | H12: 200
A16: TOTAL | H16: =SUM(H12:H15) -> 200
A17: Purpose
A18: To attend the BISU - Intelligente Publishing Inc. Training of Human Sourcebooks on November 6-7, 2025, at the Multimedia Center, BISU Main Campus
A19: I hereby certify that the above expenses are incurred as they are necessary for the above cited purpose that above goods and services were acquired from parties not issuing receipts. And that I am fully aware that wilful falsification of statements is punishable by law.
D22: Certified Correct: | G22: Noted By:
A23: Signature:
A24: Printed Name: | D24: =C8 -> ROGER E. AMOLATO | G24: =IT!A44 -> MARK JUBEN M. PILAPIL
D26: =Source!A2 -> Instructor I - Temporary | G26: Immediate Supervisor
D27: Date | G27: Date
A29: Republic of the Philippines
A30: Bohol Island State University
A31: Cogtong, Candijay, Bohol
A33: ANNEX A
A34: CERTIFICATION OF EXPENSES NOT REQUIRING RECEIPTS
A35: Pursuant to COA Circular No. 2017-001- dated June 19, 2017
A36: Name of Employee | C36: =C8 -> ROGER E. AMOLATO | G36: Employee No. | H36: =H8 -> 85448
A37: Office | B37: BOHOL ISLAND STATE UNIVERSITY
A38: Division | B38: CANDIJAY CAMPUS
A39: Particulars | H39: Amount ((₱)
A40: V-Hire Fare (Dao Terminal - Anda Terminal ) | H40: 200
A44: TOTAL | H44: =SUM(H40:H43) -> 200
A45: Purpose
A46: =A18 -> To attend the BISU - Intelligente Publishing Inc. Training of Human Sourcebooks on November 6-7, 2025, at the Multimedia Center, BISU Main Campus
A47: I hereby certify that the above expenses are incurred as they are necessary for the above cited purpose that above goods and services were acquired from parties not issuing receipts. And that I am fully aware that wilful falsification of statements is punishable by law.
D50: Certified Correct: | G50: Noted By:
A51: Signature:
A52: Printed Name: | D52: =C36 -> ROGER E. AMOLATO | G52: =G24 -> MARK JUBEN M. PILAPIL
D54: =D26 -> Instructor I - Temporary | G54: Immediate Supervisor
D55: Date | G55: Date

Sheet Certification (2)
A1: Republic of the Philippines
A2: Bohol Island State University
A3: Cogtong, Candijay, Bohol
A5: ANNEX A
A6: CERTIFICATION OF EXPENSES NOT REQUIRING RECEIPTS
A7: Pursuant to COA Circular No. 2017-001- dated June 19, 2017
A8: Name of Employee | C8: =IT!B9 -> ROGER E. AMOLATO | G8: Employee No.
A9: Office | B9: BOHOL ISLAND STATE UNIVERSITY | L9: =200+35+30+80 -> 345
A10: Division | B10: CANDIJAY CAMPUS
A11: Particulars | H11: Amount ((₱)
A12: Bus Fare (Cebu Seaport - SM Terminal) | H12: 100
A13: V-Hire Fare (Dao Terminal - Anda) | H13: 200
A16: TOTAL | H16: =SUM(H12:H15) -> 300
A17: Purpose
A18: Attended the three (3) days Face-to-face seminar on the 2nd National Sustainability Summits last July 19-21, 2023 at CTU Danao Campus, Cebu City Philippines
A19: I hereby certify that the above expenses are incurred as they are necessary for the above cited purpose that above goods and services were acquired from parties not issuing receipts. And that I am fully aware that wilful falsification of statements is punishable by law.
D22: Certified Correct: | G22: Noted By:
A23: Signature:
A24: Printed Name: | D24: =C8 -> ROGER E. AMOLATO | G24: =IT!A44 -> MARK JUBEN M. PILAPIL
D26: =Source!A2 -> Instructor I - Temporary | G26: Immediate Supervisor
D27: Date | G27: Date
A29: Republic of the Philippines
A30: Bohol Island State University
A31: Cogtong, Candijay, Bohol
A33: ANNEX A
A34: CERTIFICATION OF EXPENSES NOT REQUIRING RECEIPTS
A35: Pursuant to COA Circular No. 2017-001- dated June 19, 2017
A36: Name of Employee | C36: =C8 -> ROGER E. AMOLATO | G36: Employee No.
A37: Office | B37: BOHOL ISLAND STATE UNIVERSITY
A38: Division | B38: CANDIJAY CAMPUS
A39: Particulars | H39: Amount ((₱)
A40: =A12 -> Bus Fare (Cebu Seaport - SM Terminal) | H40: =H12 -> 100
A41: =A13 -> V-Hire Fare (Dao Terminal - Anda) | H41: =H13 -> 200
A42: =A14 -> 0 | H42: =H14 -> 0
H43: =H15 -> 0
A44: TOTAL | H44: =SUM(H40:H43) -> 300
A45: Purpose
A46: Attended the three (3) days Face-to-face seminar on the 2nd National Sustainability Summits last July 19-21, 2023 at CTU Danao Campus, Cebu City Philippines
A47: I hereby certify that the above expenses are incurred as they are necessary for the above cited purpose that above goods and services were acquired from parties not issuing receipts. And that I am fully aware that wilful falsification of statements is punishable by law.
D50: Certified Correct: | G50: Noted By:
...

Sheet Certification ('1)
A1: Republic of the Philippines
A2: Bohol Island State University
A3: Cogtong, Candijay, Bohol
A5: ANNEX A
A6: CERTIFICATION OF EXPENSES NOT REQUIRING RECEIPTS
A7: Pursuant to COA Circular No. 2017-001- dated June 19, 2017
A8: Name of Employee | C8: =IT!B9 -> ROGER E. AMOLATO | G8: Employee No.
A9: Office | B9: BOHOL ISLAND STATE UNIVERSITY
A10: Division | B10: CANDIJAY CAMPUS
A11: Particulars | H11: Amount ((₱)
A12: Bus Fare (CTU Danao - SM Terminal) | H12: 80
A13: Tricycle Fair (Tagbilaran Seaport - Lodging) | H13: 35
A14: Tricycle Fair (Lodging - Dao Terminal) | H14: 30
A16: TOTAL | H16: =SUM(H12:H15) -> 145
A17: Purpose
A18: Attended the three (3) days Face-to-face seminar on the 2nd National Sustainability Summits last July 19-21, 2023 at CTU Danao Campus, Cebu City Philippines
A19: I hereby certify that the above expenses are incurred as they are necessary for the above cited purpose that above goods and services were acquired from parties not issuing receipts. And that I am fully aware that wilful falsification of statements is punishable by law.
D22: Certified Correct: | G22: Noted By:
A23: Signature:
A24: Printed Name: | D24: =C8 -> ROGER E. AMOLATO | G24: =IT!A44 -> MARK JUBEN M. PILAPIL
D26: =Source!A2 -> Instructor I - Temporary | G26: Immediate Supervisor
D27: Date | G27: Date
A29: Republic of the Philippines
A30: Bohol Island State University
A31: Cogtong, Candijay, Bohol
A33: ANNEX A
A34: CERTIFICATION OF EXPENSES NOT REQUIRING RECEIPTS
A35: Pursuant to COA Circular No. 2017-001- dated June 19, 2017
A36: Name of Employee | C36: =C8 -> ROGER E. AMOLATO | G36: Employee No.
A37: Office | B37: BOHOL ISLAND STATE UNIVERSITY
A38: Division | B38: CANDIJAY CAMPUS
A39: Particulars | H39: Amount ((₱)
A40: Bus Fare (CTU Danao - SM Terminal) | H40: 80
A41: Tricycle Fair (Tagbilaran Seaport - Lodging) | H41: 35
A42: Tricycle Fair (Lodging - Dao Terminal) | H42: 30
A44: TOTAL | H44: =SUM(H40:H43) -> 145
A45: Purpose
A46: =A18 -> Attended the three (3) days Face-to-face seminar on the 2nd National Sustainability Summits last July 19-21, 2023 at CTU Danao Campus, Cebu City Philippines
A47: I hereby certify that the above expenses are incurred as they are necessary for the above cited purpose that above goods and services were acquired from parties not issuing receipts. And that I am fully aware that wilful falsification of statements is punishable by law.
D50: Certified Correct: | G50: Noted By:
...

Sheet ORS
L1: Appendix 11
A3: OBLIGATION REQUEST AND STATUS | K3: Serial No. : _____________________
A4: BOHOL ISLAND STATE UNIVERSITY | K4: Date : _________________________
A5: Entity Name | K5: Fund Cluster : ___________________
A6: Payee | D6: ='DV (2)'!E11 -> ROGER E. AMOLATO
A8: Office | D8: BISU Candijay Campus
A10: Address | D10: Cogtong, Candijay, Bohol
A12: Responsibility Center | D12: Particulars | I12: MFO/PAP | K12: UACS Object Code | L12: Amount
D14: 2021
D15: To:
D16: Reimbursement of monthly load allowance for the month of March, 2021 and April, 2021 in the total amount of…
L19: P | M19: 600
D34: Total | L34: P 1,200.00 | M34: =M19 -> 600
A35: A. | D35: Charges to appropriation/alloment are | I35: B.
B36: Certified: | J36: Certified: Allotment available and obligated
B37: necessary, lawful and under my direct supervision;and | J37: for the purpose/adjustment necessary as
B38: supporting documents valid, proper and legal | J38: indicated above
A42: Signature : | I42: Signature : | K42: ______________________________
A44: Printed Name: | C44: ROWENA P. MONTESCLAROS | I44: Printed Name: | K44: MARLINA S. UY
A46: Position : | C46: Administrative Officer IV | I46: Position : | K46: Bookkeeper Designate
K47: Head, Budget Division/Unit/Authorized Representative
A48: Date : | C48: ___________________________________ | I48: Date : | K48: ____________________________
A51: C. | B51: STATUS OF OBLIGATION
A52: Reference | H52: Amount
A53: Date | B53: Particulars | E53: ORS/JEV/Check/ ADA/TRA No. | H53: Obligation | I53: Payable | K53: Payment | L53: Balance
L54: Not Yet Due | M54: Due and Demandable
H55: (a) | I55: (b) | K55: (c) | L55: (a-b) | M55: (b-c)
B56: Reimbursement of
B57: monthly load
A58: =NOW() -> 45987.566 | B58: allowance | H58: =M34 -> 600 | K58: =H58 -> 600 | M58: =K58 -> 600
B60: =Source!A6 -> November 14-15, 18 and 22-23, 2022

Sheet Source
A1: ALMA MAE B. AUXTERO | B1: Payee
A2: Instructor I - Temporary | B2: Position
B3: Official Station
A4: ROWENA P. MONTESCLAROS | B4: Immediate Supervisor
A5: Administrative Officer IV | B5: Position
A6: November 14-15, 18 and 22-23, 2022 | B6: Date of Travel (mmmm dd, yyyy)
A7: to attend and participate the Crafting of University Land Use Development and Infrastructure Plan and attend University BAC Meeting | B7: Purpose
A8: JJs Seafood and Restaurant and BISU Main Campus respectively | B8: Location
